[2025-03-10T03:29:57.292+0000] {taskinstance.py:1125} INFO - Dependencies all met for dep_context=non-requeueable deps ti=<TaskInstance: penguins_workflow.load_data manual__2025-03-10T03:29:49.283068+00:00 [queued]>
[2025-03-10T03:29:57.307+0000] {taskinstance.py:1125} INFO - Dependencies all met for dep_context=requeueable deps ti=<TaskInstance: penguins_workflow.load_data manual__2025-03-10T03:29:49.283068+00:00 [queued]>
[2025-03-10T03:29:57.307+0000] {taskinstance.py:1331} INFO - Starting attempt 1 of 2
[2025-03-10T03:29:57.327+0000] {taskinstance.py:1350} INFO - Executing <Task(PythonOperator): load_data> on 2025-03-10 03:29:49.283068+00:00
[2025-03-10T03:29:57.352+0000] {standard_task_runner.py:57} INFO - Started process 102 to run task
[2025-03-10T03:29:57.369+0000] {standard_task_runner.py:84} INFO - Running: ['***', 'tasks', 'run', 'penguins_workflow', 'load_data', 'manual__2025-03-10T03:29:49.283068+00:00', '--job-id', '28', '--raw', '--subdir', 'DAGS_FOLDER/penguins_workflow.py', '--cfg-path', '/tmp/tmp480ozbue']
[2025-03-10T03:29:57.374+0000] {standard_task_runner.py:85} INFO - Job 28: Subtask load_data
[2025-03-10T03:29:57.512+0000] {task_command.py:410} INFO - Running <TaskInstance: penguins_workflow.load_data manual__2025-03-10T03:29:49.283068+00:00 [running]> on host e453b876774c
[2025-03-10T03:29:57.842+0000] {taskinstance.py:1570} INFO - Exporting env vars: AIRFLOW_CTX_DAG_OWNER='***' AIRFLOW_CTX_DAG_ID='penguins_workflow' AIRFLOW_CTX_TASK_ID='load_data' AIRFLOW_CTX_EXECUTION_DATE='2025-03-10T03:29:49.283068+00:00' AIRFLOW_CTX_TRY_NUMBER='1' AIRFLOW_CTX_DAG_RUN_ID='manual__2025-03-10T03:29:49.283068+00:00'
[2025-03-10T03:29:58.022+0000] {taskinstance.py:1847} ERROR - Task failed with exception
Traceback (most recent call last):
  File "/home/airflow/.local/lib/python3.7/site-packages/airflow/operators/python.py", line 181, in execute
    return_value = self.execute_callable()
  File "/home/airflow/.local/lib/python3.7/site-packages/airflow/operators/python.py", line 198, in execute_callable
    return self.python_callable(*self.op_args, **self.op_kwargs)
  File "/opt/airflow/dags/penguins_workflow.py", line 79, in load_data
    engine = sqlalchemy.create_engine('mysql+pymysql://model_user:model_password@mysql/model_db')
  File "<string>", line 2, in create_engine
  File "/home/airflow/.local/lib/python3.7/site-packages/sqlalchemy/util/deprecations.py", line 375, in warned
    return fn(*args, **kwargs)
  File "/home/airflow/.local/lib/python3.7/site-packages/sqlalchemy/engine/create.py", line 544, in create_engine
    dbapi = dialect_cls.dbapi(**dbapi_args)
  File "/home/airflow/.local/lib/python3.7/site-packages/sqlalchemy/dialects/mysql/pymysql.py", line 80, in dbapi
    return __import__("pymysql")
ModuleNotFoundError: No module named 'pymysql'
[2025-03-10T03:29:58.043+0000] {taskinstance.py:1373} INFO - Marking task as UP_FOR_RETRY. dag_id=penguins_workflow, task_id=load_data, execution_date=20250310T032949, start_date=20250310T032957, end_date=20250310T032958
[2025-03-10T03:29:58.060+0000] {standard_task_runner.py:109} ERROR - Failed to execute job 28 for task load_data (No module named 'pymysql'; 102)
[2025-03-10T03:29:58.106+0000] {local_task_job_runner.py:232} INFO - Task exited with return code 1
[2025-03-10T03:29:58.161+0000] {taskinstance.py:2674} INFO - 0 downstream tasks scheduled from follow-on schedule check
