[2025-03-10T03:46:23.321+0000] {taskinstance.py:1125} INFO - Dependencies all met for dep_context=non-requeueable deps ti=<TaskInstance: penguins_workflow.train_models manual__2025-03-10T03:41:00.257251+00:00 [queued]>
[2025-03-10T03:46:23.335+0000] {taskinstance.py:1125} INFO - Dependencies all met for dep_context=requeueable deps ti=<TaskInstance: penguins_workflow.train_models manual__2025-03-10T03:41:00.257251+00:00 [queued]>
[2025-03-10T03:46:23.335+0000] {taskinstance.py:1331} INFO - Starting attempt 2 of 2
[2025-03-10T03:46:23.363+0000] {taskinstance.py:1350} INFO - Executing <Task(PythonOperator): train_models> on 2025-03-10 03:41:00.257251+00:00
[2025-03-10T03:46:23.392+0000] {standard_task_runner.py:57} INFO - Started process 191 to run task
[2025-03-10T03:46:23.408+0000] {standard_task_runner.py:84} INFO - Running: ['***', 'tasks', 'run', 'penguins_workflow', 'train_models', 'manual__2025-03-10T03:41:00.257251+00:00', '--job-id', '36', '--raw', '--subdir', 'DAGS_FOLDER/penguins_workflow.py', '--cfg-path', '/tmp/tmpwne8vypf']
[2025-03-10T03:46:23.413+0000] {standard_task_runner.py:85} INFO - Job 36: Subtask train_models
[2025-03-10T03:46:23.545+0000] {task_command.py:410} INFO - Running <TaskInstance: penguins_workflow.train_models manual__2025-03-10T03:41:00.257251+00:00 [running]> on host dd1502d57320
[2025-03-10T03:46:23.726+0000] {taskinstance.py:1570} INFO - Exporting env vars: AIRFLOW_CTX_DAG_OWNER='***' AIRFLOW_CTX_DAG_ID='penguins_workflow' AIRFLOW_CTX_TASK_ID='train_models' AIRFLOW_CTX_EXECUTION_DATE='2025-03-10T03:41:00.257251+00:00' AIRFLOW_CTX_TRY_NUMBER='2' AIRFLOW_CTX_DAG_RUN_ID='manual__2025-03-10T03:41:00.257251+00:00'
[2025-03-10T03:46:23.819+0000] {taskinstance.py:1847} ERROR - Task failed with exception
Traceback (most recent call last):
  File "/home/airflow/.local/lib/python3.7/site-packages/airflow/operators/python.py", line 181, in execute
    return_value = self.execute_callable()
  File "/home/airflow/.local/lib/python3.7/site-packages/airflow/operators/python.py", line 198, in execute_callable
    return self.python_callable(*self.op_args, **self.op_kwargs)
  File "/opt/airflow/dags/penguins_workflow.py", line 129, in train_models
    os.makedirs(models_dir, exist_ok=True)
  File "/usr/local/lib/python3.7/os.py", line 213, in makedirs
    makedirs(head, exist_ok=exist_ok)
  File "/usr/local/lib/python3.7/os.py", line 223, in makedirs
    mkdir(name, mode)
PermissionError: [Errno 13] Permission denied: '/home/app'
[2025-03-10T03:46:23.841+0000] {taskinstance.py:1373} INFO - Marking task as FAILED. dag_id=penguins_workflow, task_id=train_models, execution_date=20250310T034100, start_date=20250310T034623, end_date=20250310T034623
[2025-03-10T03:46:23.864+0000] {standard_task_runner.py:109} ERROR - Failed to execute job 36 for task train_models ([Errno 13] Permission denied: '/home/app'; 191)
[2025-03-10T03:46:23.938+0000] {local_task_job_runner.py:232} INFO - Task exited with return code 1
[2025-03-10T03:46:23.996+0000] {taskinstance.py:2674} INFO - 0 downstream tasks scheduled from follow-on schedule check
